<?xml version="1.0"?>

<robot xmlns:xacro="http://ros.org/wiki/xacro" name="typepyt">

  <xacro:macro name="box_inertial" params="x y z mass *origin">
    <inertial>
      <mass value="${mass}" />
      <xacro:insert_block name="origin" />
      <inertia ixx="${0.0833333 * mass * (y*y + z*z)}" ixy="0.0" ixz="0.0"
        iyy="${0.0833333 * mass * (x*x + z*z)}" iyz="0.0"
        izz="${0.0833333 * mass * (x*x + y*y)}" />
    </inertial>
  </xacro:macro>

  <xacro:property name="material_yellow">
    <material name="yellow">
      <color rgba="${255/255} ${226/255} ${0/255} 1"/>
    </material>
  </xacro:property>

  <xacro:macro name="mimic_joint_plugin_gazebo" params="name_prefix parent_joint mimic_joint has_pid:=false multiplier:=1.0 offset:=0 sensitiveness:=0.0 max_effort:=1.0 robot_namespace:=''">
    <gazebo>
      <plugin name="${name_prefix}mimic_joint_plugin" filename="libroboticsgroup_gazebo_mimic_joint_plugin.so">
        <joint>${parent_joint}</joint>
        <mimicJoint>${mimic_joint}</mimicJoint>
        <xacro:if value="${has_pid}">                     <!-- if set to true, PID parameters from "/gazebo_ros_control/pid_gains/${mimic_joint}" are loaded -->
          <hasPID />
        </xacro:if>
        <multiplier>${multiplier}</multiplier>
        <offset>${offset}</offset>
        <sensitiveness>${sensitiveness}</sensitiveness>   <!-- if absolute difference between setpoint and process value is below this threshold, do nothing; 0.0 = disable [rad] -->
        <maxEffort>${max_effort}</maxEffort>              <!-- only taken into account if has_pid:=true [Nm] -->
        <xacro:unless value="${robot_namespace == ''}">
          <robotNamespace>($robot_namespace)</robotNamespace>
        </xacro:unless>
      </plugin>
    </gazebo>
  </xacro:macro>

  <xacro:macro name="controller_plugin_gazebo" params="robot_namespace:=''">
    <gazebo>
      <plugin name="gazebo_ros_control" filename="libgazebo_ros_control.so">
        <xacro:unless value="${robot_namespace == ''}">
          <robotNamespace>($robot_namespace)</robotNamespace>
        </xacro:unless>
        <controlPeriod>0.001</controlPeriod>
      </plugin>
    </gazebo>
  </xacro:macro>

  <controller_plugin_gazebo />

  <!--world + base_link -->
  
  <link name="world" />
 
  <joint name="fixed" type="fixed">
    <origin xyz="0.0 0.0 0.0" /> 
    <parent link="world" />
    <child link="base_link" />
  </joint>

  <link name="base_link">
    <visual>
      <origin xyz="0 0 0"/>
      <geometry>
        <box size="0.95 1.425 0.2"/>
      </geometry>
      <xacro:insert_block name="material_yellow"/>
    </visual>
    <collision> 
      <origin xyz="0 0 0"/>
      <geometry>
        <box size="0.95 1.425 0.2"/>
      </geometry>
    </collision>
    <xacro:box_inertial mass="1.0" x="0.18" y="0.8" z="0.25">
      <origin xyz="0 0 0" />
    </xacro:box_inertial>
  </link>
  <gazebo reference="base_link">
    <material>Gazebo/Yellow</material>
  </gazebo>

  <!-- base_link + torso -->

  <joint name="hip" type="revolute">
    <origin xyz="0 0 0.12" rpy="0 0 0"/>
    <parent link="base_link"/>
    <child link="torso"/>
    <axis xyz="0 0 1"/>
    <limit lower="0.0" upper="3.14" velocity="1.0" effort="30" />
    <dynamics damping="0.05" friction="0.0" />
  </joint>

  <link name="torso">
    <visual>
      <origin xyz="0 0 0.25"/>
      <geometry>
        <box size="0.53 0.55 0.45"/>
      </geometry>
      <xacro:insert_block name="material_yellow" />
    </visual>
    <collision>
      <origin xyz="0 0 0.25"/>
      <geometry>
        <box size="0.53 0.55 0.45"/>
      </geometry>
    </collision>
    <xacro:box_inertial mass="1.0" x="0.04" y="0.04" z="0.05">
      <origin xyz="0 0 0.25"/>
    </xacro:box_inertial>
  </link>
  <gazebo reference="torso">
    <material>Gazebo/Yellow</material>
  </gazebo>

  <transmission name="tran0">
    <type>transmission_interface/SimpleTransmission</type>
    <joint name="hip">
      <hardwareInterface>hardware_interface/PositionJointInterface</hardwareInterface>
    </joint>
    <actuator name="motor0">
      <hardwareInterface>PositionJointInterface</hardwareInterface>
      <mechanicalReduction>1</mechanicalReduction>
    </actuator>
  </transmission>
    
  <!-- torso + upper_arm -->

  <joint name="shoulder" type="revolute">
    <origin xyz="0.2 0 0.3" rpy="0 -1.5708 0"/>
    <parent link="torso"/>
    <child link="upper_arm"/>
    <axis xyz="0 1 0"/>
    <limit lower="0.52" upper="2.79" velocity="1.0" effort="30.0" />
    <dynamics damping="0.05" friction="0.0" />
  </joint>

  <link name="upper_arm">
    <visual>
      <origin xyz="0 0 0.4"/>
      <geometry>
        <box size="0.05 0.05 0.8"/>
      </geometry>
      <xacro:insert_block name="material_yellow" />
    </visual>
    <collision>
      <origin xyz="0 0 0.4"/>
      <geometry>
        <box size="0.05 0.05 0.8"/>
      </geometry>
    </collision>
    <xacro:box_inertial mass="1.0" x="0.16" y="0.16" z="0.32">
      <origin xyz="0 0 0"/>
    </xacro:box_inertial>
  </link>
  <gazebo reference="upper_arm">
    <material>Gazebo/Yellow</material>
  </gazebo>

  <transmission name="tran1">
    <type>transmission_interface/SimpleTransmission</type>
    <joint name="shoulder">
      <hardwareInterface>hardware_interface/PositionJointInterface</hardwareInterface>
    </joint>
    <actuator name="motor1">
      <hardwareInterface>PositionJointInterface</hardwareInterface>
      <mechanicalReduction>1</mechanicalReduction>
    </actuator>
  </transmission>  

  <!-- upper_arm + upper_arm1 -->

  <joint name="elbow" type="revolute">
    <origin xyz="0 0 0.8" rpy="0 3.36 0" />
    <parent link="upper_arm" />
    <child link="upper_arm1" />
    <axis xyz="0 -1 0"/>
    <limit lower="0.87" upper="2.44" velocity="1.0" effort="30.0" />
    <mimic joint="shoulder" multiplier="1" offset="0" />
    <dynamics damping="0.0" friction="0.0" />
  </joint>

  <xacro:mimic_joint_plugin_gazebo name_prefix="elbow"
    parent_joint="shoulder" mimic_joint="elbow"
    has_pid="true" multiplier="1.0" max_effort="10.0" />

  <link name="upper_arm1">
    <visual>
      <origin xyz="0 0 0.04"/>
      <geometry>
        <box size="0.05 0.05 0.01"/>
      </geometry>
      <xacro:insert_block name="material_yellow" />
    </visual>
    <collision>
      <origin xyz="0 0 0.4"/>
      <geometry>
        <box size="0.05 0.05 0.01"/>
      </geometry>
    </collision>
    <xacro:box_inertial mass="1.0" x="0.04" y="0.04" z="0.05">
      <origin xyz="0.05 0.05 0.01"/>
    </xacro:box_inertial>
  </link>
  <gazebo reference="upper_arm1">
    <material>Gazebo/Yellow</material>
  </gazebo>

  <!-- upper_arm1 + lower_arm -->

  <joint name="elbow1" type="revolute">
    <origin xyz="0 0 0.01" rpy="0 3.36 0"/>
    <parent link="upper_arm1"/>
    <child link="lower_arm"/>
    <axis xyz="0 -1 0"/>
    <limit lower="1.75" upper="3.0" velocity="1.0" effort="30.0" />
    <dynamics damping="0.05" friction="0.0" />
  </joint>

  <link name="lower_arm">
    <visual>
      <origin xyz="0 0 0.4"/>
      <geometry>
        <box size="0.05 0.05 0.79"/>
      </geometry>
      <xacro:insert_block name="material_yellow" />
    </visual>
    <collision>
      <origin xyz="0 0 0.4"/>
      <geometry>
        <box size="0.05 0.05 0.79"/>
      </geometry>
    </collision>
    <xacro:box_inertial mass="1.0" x="0.16" y="0.16" z="0.32">
      <origin xyz="0 0 0.4"/>
    </xacro:box_inertial>
  </link>
  <gazebo reference="lower_arm">
    <material>Gazebo/Yellow</material>
  </gazebo>

  <transmission name="tran2">
    <type>transmission_interface/SimpleTransmission</type>
    <joint name="elbow1">
      <hardwareInterface>hardware_interface/PositionJointInterface</hardwareInterface>
    </joint>
    <actuator name="motor2">
      <hardwareInterface>PositionJointInterface</hardwareInterface>
      <mechanicalReduction>1</mechanicalReduction>
    </actuator>
  </transmission>

  <!-- lower_arm + hand -->

  <joint name="wrist" type="revolute">
    <origin xyz="0 0 0.805" rpy="0 0 0"/>
    <parent link="lower_arm"/>
    <child link="hand"/>
    <axis xyz="1 0 0"/>
    <limit lower="0.0" upper="2.7" velocity="1.0" effort="30.0" />
    <dynamics damping="0.05" friction="0.0" />
  </joint>

  <link name="hand">
    <visual>
      <origin xyz="0 0 0"/>
      <geometry>
        <box size="0.05 0.05 0.2"/>
      </geometry>
      <xacro:insert_block name="material_yellow" />
    </visual>
    <collision>
      <origin xyz="0 0 0"/>
      <geometry>
        <box size="0.05 0.05 0.2"/>
      </geometry>
    </collision>
    <xacro:box_inertial mass="1.0" x="0.0004" y="0.0004" z="0.002">
      <origin xyz="0 0 0"/>
    </xacro:box_inertial>
  </link>
  <gazebo reference="hand">
    <material>Gazebo/Yellow</material>
  </gazebo>

  <transmission name="tran3">
    <type>transmission_interface/SimpleTransmission</type>
    <joint name="wrist">
      <hardwareInterface>hardware_interface/PositionJointInterface</hardwareInterface>
    </joint>
    <actuator name="motor3">
      <hardwareInterface>PositionJointInterface</hardwareInterface>
      <mechanicalReduction>1</mechanicalReduction>
    </actuator>
  </transmission>


  <gazebo>
    <plugin name="control" filename="libgazebo_ros_control.so"/>
  </gazebo>
  <gazebo>
    <plugin name="joint_state_publisher" filename="libgazebo_ros_joint_state_publisher.so">
      <jointName>hip, shoulder, elbow, wrist</jointName>
    </plugin>
  </gazebo>
</robot>
